2023-06-19 12:12:44,104 INFO    StreamThr :17094 [internal.py:wandb_internal():86] W&B internal server running at pid: 17094, started at: 2023-06-19 12:12:44.104207
2023-06-19 12:12:44,107 DEBUG   HandlerThread:17094 [handler.py:handle_request():144] handle_request: status
2023-06-19 12:12:44,109 INFO    WriterThread:17094 [datastore.py:open_for_write():85] open: ./wandb/run-20230619_121244-ahyhfhrj/run-ahyhfhrj.wandb
2023-06-19 12:12:44,110 DEBUG   SenderThread:17094 [sender.py:send():369] send: header
2023-06-19 12:12:44,131 DEBUG   SenderThread:17094 [sender.py:send():369] send: run
2023-06-19 12:12:44,134 INFO    SenderThread:17094 [sender.py:_maybe_setup_resume():737] checking resume status for nlp/hw2/ahyhfhrj
2023-06-19 12:12:44,642 ERROR   SenderThread:17094 [internal_api.py:execute():323] 403 response executing GraphQL.
2023-06-19 12:12:44,642 ERROR   SenderThread:17094 [internal_api.py:execute():324] {"errors":[{"message":"permission denied","path":["upsertBucket"],"extensions":{"code":"PERMISSION_ERROR"}}],"data":{"upsertBucket":null}}
2023-06-19 12:12:44,643 ERROR   SenderThread:17094 [sender.py:send_run():955] It appears that you do not have permission to access the requested resource. Please reach out to the project owner to grant you access. If you have the correct permissions, verify that there are no issues with your networking setup.(Error 403: Forbidden)
Traceback (most recent call last):
  File "/home/andrea/miniconda3/envs/nlp2023-hw2/lib/python3.9/site-packages/wandb/sdk/lib/retry.py", line 131, in __call__
    result = self._call_fn(*args, **kwargs)
  File "/home/andrea/miniconda3/envs/nlp2023-hw2/lib/python3.9/site-packages/wandb/sdk/internal/internal_api.py", line 320, in execute
    return self.client.execute(*args, **kwargs)  # type: ignore
  File "/home/andrea/miniconda3/envs/nlp2023-hw2/lib/python3.9/site-packages/wandb/vendor/gql-0.2.0/wandb_gql/client.py", line 52, in execute
    result = self._get_result(document, *args, **kwargs)
  File "/home/andrea/miniconda3/envs/nlp2023-hw2/lib/python3.9/site-packages/wandb/vendor/gql-0.2.0/wandb_gql/client.py", line 60, in _get_result
    return self.transport.execute(document, *args, **kwargs)
  File "/home/andrea/miniconda3/envs/nlp2023-hw2/lib/python3.9/site-packages/wandb/sdk/lib/gql_request.py", line 56, in execute
    request.raise_for_status()
  File "/home/andrea/miniconda3/envs/nlp2023-hw2/lib/python3.9/site-packages/requests/models.py", line 960, in raise_for_status
    raise HTTPError(http_error_msg, response=self)
requests.exceptions.HTTPError: 403 Client Error: Forbidden for url: https://api.wandb.ai/graphql

During handling of the above exception, another exception occurred:

Traceback (most recent call last):
  File "/home/andrea/miniconda3/envs/nlp2023-hw2/lib/python3.9/site-packages/wandb/sdk/internal/sender.py", line 953, in send_run
    self._init_run(run, config_value_dict)
  File "/home/andrea/miniconda3/envs/nlp2023-hw2/lib/python3.9/site-packages/wandb/sdk/internal/sender.py", line 991, in _init_run
    server_run, inserted, server_messages = self._api.upsert_run(
  File "/home/andrea/miniconda3/envs/nlp2023-hw2/lib/python3.9/site-packages/wandb/apis/normalize.py", line 73, in wrapper
    raise err
  File "/home/andrea/miniconda3/envs/nlp2023-hw2/lib/python3.9/site-packages/wandb/apis/normalize.py", line 41, in wrapper
    return func(*args, **kwargs)
  File "/home/andrea/miniconda3/envs/nlp2023-hw2/lib/python3.9/site-packages/wandb/sdk/internal/internal_api.py", line 1727, in upsert_run
    response = self.gql(
  File "/home/andrea/miniconda3/envs/nlp2023-hw2/lib/python3.9/site-packages/wandb/sdk/internal/internal_api.py", line 292, in gql
    ret = self._retry_gql(
  File "/home/andrea/miniconda3/envs/nlp2023-hw2/lib/python3.9/site-packages/wandb/sdk/lib/retry.py", line 147, in __call__
    retry_timedelta_triggered = check_retry_fn(e)
  File "/home/andrea/miniconda3/envs/nlp2023-hw2/lib/python3.9/site-packages/wandb/util.py", line 908, in check_retry_fn
    return fallback_retry_fn(e)
  File "/home/andrea/miniconda3/envs/nlp2023-hw2/lib/python3.9/site-packages/wandb/util.py", line 850, in no_retry_auth
    raise CommError(
wandb.errors.CommError: It appears that you do not have permission to access the requested resource. Please reach out to the project owner to grant you access. If you have the correct permissions, verify that there are no issues with your networking setup.(Error 403: Forbidden)
2023-06-19 12:12:49,646 DEBUG   HandlerThread:17094 [handler.py:handle_request():144] handle_request: status_report
2023-06-19 12:12:54,647 DEBUG   HandlerThread:17094 [handler.py:handle_request():144] handle_request: status_report
2023-06-19 12:12:59,648 DEBUG   HandlerThread:17094 [handler.py:handle_request():144] handle_request: status_report
2023-06-19 12:13:04,650 DEBUG   HandlerThread:17094 [handler.py:handle_request():144] handle_request: status_report
2023-06-19 12:13:09,651 DEBUG   HandlerThread:17094 [handler.py:handle_request():144] handle_request: status_report
2023-06-19 12:13:14,651 DEBUG   HandlerThread:17094 [handler.py:handle_request():144] handle_request: status_report
2023-06-19 12:13:19,652 DEBUG   HandlerThread:17094 [handler.py:handle_request():144] handle_request: status_report
2023-06-19 12:13:24,653 DEBUG   HandlerThread:17094 [handler.py:handle_request():144] handle_request: status_report
2023-06-19 12:13:29,655 DEBUG   HandlerThread:17094 [handler.py:handle_request():144] handle_request: status_report
2023-06-19 12:13:34,656 DEBUG   HandlerThread:17094 [handler.py:handle_request():144] handle_request: status_report
2023-06-19 12:13:39,658 DEBUG   HandlerThread:17094 [handler.py:handle_request():144] handle_request: status_report
2023-06-19 12:13:44,660 DEBUG   HandlerThread:17094 [handler.py:handle_request():144] handle_request: status_report
2023-06-19 12:13:49,660 DEBUG   HandlerThread:17094 [handler.py:handle_request():144] handle_request: status_report
2023-06-19 12:13:54,661 DEBUG   HandlerThread:17094 [handler.py:handle_request():144] handle_request: status_report
2023-06-19 12:13:59,662 DEBUG   HandlerThread:17094 [handler.py:handle_request():144] handle_request: status_report
2023-06-19 12:14:04,663 DEBUG   HandlerThread:17094 [handler.py:handle_request():144] handle_request: status_report
2023-06-19 12:14:09,664 DEBUG   HandlerThread:17094 [handler.py:handle_request():144] handle_request: status_report
2023-06-19 12:14:14,664 DEBUG   HandlerThread:17094 [handler.py:handle_request():144] handle_request: status_report
2023-06-19 12:14:19,665 DEBUG   HandlerThread:17094 [handler.py:handle_request():144] handle_request: status_report
2023-06-19 12:14:24,666 DEBUG   HandlerThread:17094 [handler.py:handle_request():144] handle_request: status_report
2023-06-19 12:14:29,667 DEBUG   HandlerThread:17094 [handler.py:handle_request():144] handle_request: status_report
2023-06-19 12:14:34,668 DEBUG   HandlerThread:17094 [handler.py:handle_request():144] handle_request: status_report
2023-06-19 12:14:39,669 DEBUG   HandlerThread:17094 [handler.py:handle_request():144] handle_request: status_report
2023-06-19 12:14:44,671 DEBUG   HandlerThread:17094 [handler.py:handle_request():144] handle_request: status_report
2023-06-19 12:14:49,672 DEBUG   HandlerThread:17094 [handler.py:handle_request():144] handle_request: status_report
